<?xml version="1.0" encoding="utf-8"?>
<robot
  name="Lens_Right_Arm_Description">
  <link
    name="Base_Link">
    <inertial>
      <origin
        xyz="-0.00222338943153113 -7.21477586634144E-07 0.290469759753077"
        rpy="0 0 0" />
      <mass
        value="11.5498443972996" />
      <inertia
        ixx="0.5885597835799"
        ixy="3.1554820713728E-09"
        ixz="-0.000471193074627488"
        iyy="0.58795222479349"
        iyz="4.94265597646443E-08"
        izz="0.468956501545227" />
    </inertial>
    <visual>
      <origin
        xyz="0 0 0"
        rpy="0 0 0" />
      <geometry>
        <mesh
          filename="package://lens_dual_arm_description/meshes/Base_Link.STL" /> 
      </geometry>
      <material
        name="">
        <color
          rgba="0.792156862745098 0.819607843137255 0.933333333333333 1" />
      </material>
    </visual>
    <collision>
      <origin
        xyz="0 0 0"
        rpy="0 0 0" />
      <geometry>
        <mesh
          filename="package://lens_dual_arm_description/meshes/Base_Link.STL" />
      </geometry>
    </collision>
  </link>
  <link
    name="Right_Shoulder_Base_Link">
    <inertial>
      <origin
        xyz="-1.99267264776488E-09 -0.0659218361820058 3.30808307413832E-08"
        rpy="0 0 0" />
      <mass
        value="0.924033111595576" />
      <inertia
        ixx="0.000808213882214251"
        ixy="2.95678180150087E-11"
        ixz="8.08908965209071E-09"
        iyy="0.000931574847368185"
        iyz="-4.02248117355149E-10"
        izz="0.000673662555326232" />
    </inertial>
    <visual>
      <origin
        xyz="0 0 0"
        rpy="0 0 0" />
      <geometry>
        <mesh
          filename="package://lens_dual_arm_description/meshes/Right_Shoulder_Base_Link.STL" />
      </geometry>
      <material
        name="">
        <color
          rgba="0.898039215686275 0.917647058823529 0.929411764705882 1" />
      </material>
    </visual>
    <collision>
      <origin
        xyz="0 0 0"
        rpy="0 0 0" />
      <geometry>
        <mesh
          filename="package://lens_dual_arm_description/meshes/Right_Shoulder_Base_Link.STL" />
      </geometry>
    </collision>
  </link>
  <joint
    name="Right_Shoulder_Base_Joint"
    type="fixed">
    <origin
      xyz="0 0 1.217"
      rpy="0 0 0" />
    <parent
      link="Base_Link" />
    <child
      link="Right_Shoulder_Base_Link" />
    <axis
      xyz="0 0 0" />
  </joint>
  <link
    name="Right_Shoulder_Pitch_Link">
    <inertial>
      <origin
        xyz="0.000550445937296118 -0.0663446867698749 3.85924345147615E-07"
        rpy="0 0 0" />
      <mass
        value="1.03708373831885" />
      <inertia
        ixx="0.000979917881985241"
        ixy="4.19930465301815E-05"
        ixz="-2.22495649895194E-11"
        iyy="0.0006061320567727"
        iyz="4.72594631084341E-10"
        izz="0.000805446222765678" />
    </inertial>
    <visual>
      <origin
        xyz="0 0 0"
        rpy="0 0 0" />
      <geometry>
        <mesh
          filename="package://lens_dual_arm_description/meshes/Right_Shoulder_Pitch_Link.STL" />
      </geometry>
      <material
        name="">
        <color
          rgba="0.890196078431372 0.890196078431372 0.913725490196078 1" />
      </material>
    </visual>
    <collision>
      <origin
        xyz="0 0 0"
        rpy="0 0 0" />
      <geometry>
        <mesh
          filename="package://lens_dual_arm_description/meshes/Right_Shoulder_Pitch_Link.STL" />
      </geometry>
    </collision>
  </link>
  <joint
    name="Right_Shoulder_Pitch_Joint"
    type="revolute">
    <origin
      xyz="0 -0.096 0"
      rpy="0 0 0" />
    <parent
      link="Right_Shoulder_Base_Link" />
    <child
      link="Right_Shoulder_Pitch_Link" />
    <axis
      xyz="0 -1 0" />
    <limit
      lower="-1.05"
      upper="2.97"
      effort="80"
      velocity="10" />
  </joint>
  <link
    name="Right_Shoulder_Roll_Link">
    <inertial>
      <origin
        xyz="-0.0328494705864756 -5.65907654070941E-10 -0.0818728578417687"
        rpy="0 0 0" />
      <mass
        value="0.61158472274931" />
      <inertia
        ixx="0.000491306613863732"
        ixy="6.1822268286409E-11"
        ixz="-5.06965158681799E-07"
        iyy="0.000474492050561758"
        iyz="-2.5869655543651E-08"
        izz="0.000257742401525433" />
    </inertial>
    <visual>
      <origin
        xyz="0 0 0"
        rpy="0 0 0" />
      <geometry>
        <mesh
          filename="package://lens_dual_arm_description/meshes/Right_Shoulder_Roll_Link.STL" />
      </geometry>
      <material
        name="">
        <color
          rgba="0.898039215686275 0.917647058823529 0.929411764705882 1" />
      </material>
    </visual>
    <collision>
      <origin
        xyz="0 0 0"
        rpy="0 0 0" />
      <geometry>
        <mesh
          filename="package://lens_dual_arm_description/meshes/Right_Shoulder_Roll_Link.STL" />
      </geometry>
    </collision>
  </link>
  <joint
    name="Right_Shoulder_Roll_Joint"
    type="revolute">
    <origin
      xyz="0.0328 -0.075 0"
      rpy="0 0 0" />
    <parent
      link="Right_Shoulder_Pitch_Link" />
    <child
      link="Right_Shoulder_Roll_Link" />
    <axis
      xyz="1 0 0" />
    <limit
      lower="-3.49"
      upper="0.35"
      effort="80"
      velocity="10" />
  </joint>
  <link
    name="Right_Shoulder_Yaw_Link">
    <inertial>
      <origin
        xyz="0.00682314676154521 -4.46512945424526E-05 -0.130199530724097"
        rpy="0 0 0" />
      <mass
        value="0.600776606697812" />
      <inertia
        ixx="0.000473916613527744"
        ixy="7.72324077414352E-08"
        ixz="5.90958237468826E-06"
        iyy="0.000448035733659395"
        iyz="1.79115600066026E-07"
        izz="0.000256235205802589" />
    </inertial>
    <visual>
      <origin
        xyz="0 0 0"
        rpy="0 0 0" />
      <geometry>
        <mesh
          filename="package://lens_dual_arm_description/meshes/Right_Shoulder_Yaw_Link.STL" />
      </geometry>
      <material
        name="">
        <color
          rgba="0.890196078431372 0.890196078431372 0.913725490196078 1" />
      </material>
    </visual>
    <collision>
      <origin
        xyz="0 0 0"
        rpy="0 0 0" />
      <geometry>
        <mesh
          filename="package://lens_dual_arm_description/meshes/Right_Shoulder_Yaw_Link.STL" />
      </geometry>
    </collision>
  </link>
  <joint
    name="Right_Shoulder_Yaw_Joint"
    type="revolute">
    <origin
      xyz="-0.0328 0 -0.12"
      rpy="0 0 0" />
    <parent
      link="Right_Shoulder_Roll_Link" />
    <child
      link="Right_Shoulder_Yaw_Link" />
    <axis
      xyz="0 0 -1" />
    <limit
      lower="-2.79"
      upper="2.79"
      effort="36"
      velocity="10" />
  </joint>
  <link
    name="Right_Elbow_Pitch_Link">
    <inertial>
      <origin
        xyz="-0.0090491523715236 0.0323897268652624 -0.0740069723660367"
        rpy="0 0 0" />
      <mass
        value="0.571476288532121" />
      <inertia
        ixx="0.000373555591273092"
        ixy="-3.30108376678752E-08"
        ixz="-1.15595088255074E-05"
        iyy="0.000376114093665451"
        iyz="1.49444083196836E-07"
        izz="0.00022821832724163" />
    </inertial>
    <visual>
      <origin
        xyz="0 0 0"
        rpy="0 0 0" />
      <geometry>
        <mesh
          filename="package://lens_dual_arm_description/meshes/Right_Elbow_Pitch_Link.STL" />
      </geometry>
      <material
        name="">
        <color
          rgba="0.792156862745098 0.819607843137255 0.933333333333333 1" />
      </material>
    </visual>
    <collision>
      <origin
        xyz="0 0 0"
        rpy="0 0 0" />
      <geometry>
        <mesh
          filename="package://lens_dual_arm_description/meshes/Right_Elbow_Pitch_Link.STL" />
      </geometry>
    </collision>
  </link>
  <joint
    name="Right_Elbow_Pitch_Joint"
    type="revolute">
    <origin
      xyz="0.0095 -0.0325 -0.15"
      rpy="0 0 0" />
    <parent
      link="Right_Shoulder_Yaw_Link" />
    <child
      link="Right_Elbow_Pitch_Link" />
    <axis
      xyz="0 -1 0" />
    <limit
      lower="-0.21"
      upper="2.355"
      effort="36"
      velocity="10" />
  </joint>
  <link
    name="Right_Wrist_Yaw_Link">
    <inertial>
      <origin
        xyz="-3.68521239685251E-08 -0.0065016641372202 -0.0555925647837076"
        rpy="0 0 0" />
      <mass
        value="0.47758723622525" />
      <inertia
        ixx="0.000252124777274285"
        ixy="2.5638314061415E-10"
        ixz="-8.40240519042393E-10"
        iyy="0.00023075116324108"
        iyz="1.49094977439206E-05"
        izz="0.000224026583523099" />
    </inertial>
    <visual>
      <origin
        xyz="0 0 0"
        rpy="0 0 0" />
      <geometry>
        <mesh
          filename="package://lens_dual_arm_description/meshes/Right_Wrist_Yaw_Link.STL" />
      </geometry>
      <material
        name="">
        <color
          rgba="0.890196078431372 0.890196078431372 0.913725490196078 1" />
      </material>
    </visual>
    <collision>
      <origin
        xyz="0 0 0"
        rpy="0 0 0" />
      <geometry>
        <mesh
          filename="package://lens_dual_arm_description/meshes/Right_Wrist_Yaw_Link.STL" />
      </geometry>
    </collision>
  </link>
  <joint
    name="Right_Wrist_Yaw_Joint"
    type="revolute">
    <origin
      xyz="-0.0095 0.0325 -0.11"
      rpy="0 0 0" />
    <parent
      link="Right_Elbow_Pitch_Link" />
    <child
      link="Right_Wrist_Yaw_Link" />
    <axis
      xyz="0 0 -1" />
    <limit
      lower="-2.79"
      upper="2.79"
      effort="36"
      velocity="10" />
  </joint>
  <link
    name="Right_Wrist_Pitch_Link">
    <inertial>
      <origin
        xyz="-0.00712530104384592 -0.0182054860115446 -0.0596462537825272"
        rpy="0 0 0" />
      <mass
        value="0.464091420162859" />
      <inertia
        ixx="0.000228236803974143"
        ixy="2.40015869616491E-06"
        ixz="5.18112746327142E-06"
        iyy="0.000268369019194987"
        iyz="-7.34023927836005E-06"
        izz="0.000199899053944628" />
    </inertial>
    <visual>
      <origin
        xyz="0 0 0"
        rpy="0 0 0" />
      <geometry>
        <mesh
          filename="package://lens_dual_arm_description/meshes/Right_Wrist_Pitch_Link.STL" />
      </geometry>
      <material
        name="">
        <color
          rgba="0.898039215686275 0.917647058823529 0.929411764705882 1" />
      </material>
    </visual>
    <collision>
      <origin
        xyz="0 0 0"
        rpy="0 0 0" />
      <geometry>
        <mesh
          filename="package://lens_dual_arm_description/meshes/Right_Wrist_Pitch_Link.STL" />
      </geometry>
    </collision>
  </link>
  <joint
    name="Right_Wrist_Pitch_Joint"
    type="revolute">
    <origin
      xyz="0 0.022 -0.06"
      rpy="0 0 0" />
    <parent
      link="Right_Wrist_Yaw_Link" />
    <child
      link="Right_Wrist_Pitch_Link" />
    <axis
      xyz="0 1 0" />
    <limit
      lower="-1.57"
      upper="1.57"
      effort="36"
      velocity="10" />
  </joint>
  <link
    name="Right_Wrist_Roll_Link">
    <inertial>
      <origin
        xyz="-0.00727022599879533 2.82407791596384E-10 -0.0363234197668277"
        rpy="0 0 0" />
      <mass
        value="0.073752863664096" />
      <inertia
        ixx="5.50396554373169E-05"
        ixy="-8.73979797649329E-14"
        ixz="-1.46653059719206E-05"
        iyy="5.8030871481939E-05"
        iyz="-4.48880576916881E-13"
        izz="4.14743760983857E-05" />
    </inertial>
    <visual>
      <origin
        xyz="0 0 0"
        rpy="0 0 0" />
      <geometry>
        <mesh
          filename="package://lens_dual_arm_description/meshes/Right_Wrist_Roll_Link.STL" />
      </geometry>
      <material
        name="">
        <color
          rgba="0.890196078431372 0.890196078431372 0.913725490196078 1" />
      </material>
    </visual>
    <collision>
      <origin
        xyz="0 0 0"
        rpy="0 0 0" />
      <geometry>
        <mesh
          filename="package://lens_dual_arm_description/meshes/Right_Wrist_Roll_Link.STL" />
      </geometry>
    </collision>
  </link>
  <joint
    name="Right_Wrist_Roll_Joint"
    type="revolute">
    <origin
      xyz="0.0225 -0.022 -0.064"
      rpy="0 0 0" />
    <parent
      link="Right_Wrist_Pitch_Link" />
    <child
      link="Right_Wrist_Roll_Link" />
    <axis
      xyz="1 0 0" />
    <limit
      lower="-1.57"
      upper="1.57"
      effort="36"
      velocity="10" />
  </joint>
</robot>
