<?xml version='1.0' encoding='utf-8'?>
<robot name="arm_lingzuV2_right">
  <link name="base_link">
    <inertial>
      <origin xyz="1.6001E-05 9.5162E-07 -1.3045E-05" rpy="0 0 0" />
      <mass value="3.5229" />
      <inertia ixx="0.0038728" ixy="-5.3821E-11" ixz="2.031E-09" iyy="0.0057823" iyz="2.5825E-07" izz="0.0039027" />
    </inertial>
    <visual>
      <origin xyz="0 0 0" rpy="0 0 0" />
      <geometry>
        <mesh filename="meshes/base_link.STL" />
      </geometry>
      <material name="">
        <color rgba="0.75294 0.75294 0.75294 1" />
      </material>
    </visual>
    <collision>
      <origin xyz="0 0 0" rpy="0 0 0" />
      <geometry>
        <mesh filename="meshes/base_link.STL" />
      </geometry>
    </collision>
  </link>
  <link name="R1_Link">
    <inertial>
      <origin xyz="0.0055078 -0.066869 8.2128E-06" rpy="0 0 0" />
      <mass value="1.1563" />
      <inertia ixx="0.0015293" ixy="-3.5153E-07" ixz="6.4672E-07" iyy="0.00081944" iyz="1.2213E-05" izz="0.00086485" />
    </inertial>
    <visual>
      <origin xyz="0 0 0" rpy="0 0 0" />
      <geometry>
        <mesh filename="meshes/R1_Link.STL" />
      </geometry>
      <material name="">
        <color rgba="0.75294 0.75294 0.75294 1" />
      </material>
    </visual>
    <collision>
      <origin xyz="0 0 0" rpy="0 0 0" />
      <geometry>
        <mesh filename="meshes/R1_Link.STL" />
      </geometry>
    </collision>
  </link>
  <joint name="R1_JOINT" type="revolute">
    <origin xyz="0 -0.1435 0" rpy="0 0 0" />
    <parent link="base_link" />
    <child link="R1_Link" />
    <axis xyz="0 1 0" />
    <limit lower="-3.75" upper="2.18" effort="60" velocity="18.84" />
  </joint>
  <link name="R2_Link">
    <inertial>
      <origin xyz="-0.03112 0.00090484 -0.10582" rpy="0 0 0" />
      <mass value="0.87778" />
      <inertia ixx="0.00059858" ixy="-2.0676E-07" ixz="1.5547E-07" iyy="0.00056467" iyz="-1.2297E-06" izz="0.00082509" />
    </inertial>
    <visual>
      <origin xyz="0 0 0" rpy="0 0 0" />
      <geometry>
        <mesh filename="meshes/R2_Link.STL" />
      </geometry>
      <material name="">
        <color rgba="0.75294 0.75294 0.75294 1" />
      </material>
    </visual>
    <collision>
      <origin xyz="0 0 0" rpy="0 0 0" />
      <geometry>
        <mesh filename="meshes/R2_Link.STL" />
      </geometry>
    </collision>
  </link>
  <joint name="R2_JOINT" type="revolute">
    <origin xyz="0.03125 -0.0715 0" rpy="0 0 0" />
    <parent link="R1_Link" />
    <child link="R2_Link" />
    <axis xyz="-1 0 0" />
    <limit lower="-0.19" upper="3.33" effort="60" velocity="18.84" />
  </joint>
  <link name="R3_Link">
    <inertial>
      <origin xyz="-7.8768E-05 -0.0021217 -0.083919" rpy="0 0 0" />
      <mass value="1.2358" />
      <inertia ixx="0.0005503" ixy="6.4654E-08" ixz="-4.5141E-08" iyy="0.00084665" iyz="-5.052E-07" izz="0.00058804" />
    </inertial>
    <visual>
      <origin xyz="0 0 0" rpy="0 0 0" />
      <geometry>
        <mesh filename="meshes/R3_Link.STL" />
      </geometry>
      <material name="">
        <color rgba="0.75294 0.75294 0.75294 1" />
      </material>
    </visual>
    <collision>
      <origin xyz="0 0 0" rpy="0 0 0" />
      <geometry>
        <mesh filename="meshes/R3_Link.STL" />
      </geometry>
    </collision>
  </link>
  <joint name="R3_JOINT" type="revolute">
    <origin xyz="-0.03125 0 -0.147" rpy="0 0 0" />
    <parent link="R2_Link" />
    <child link="R3_Link" />
    <axis xyz="0 0 1" />
    <limit lower="-2.26" upper="2.26" effort="17" velocity="37.68" />
  </joint>
  <link name="R4_Link">
    <inertial>
      <origin xyz="-1.0072E-05 0.026762 -0.095637" rpy="0 0 0" />
      <mass value="0.53266" />
      <inertia ixx="0.00024512" ixy="5.9425E-09" ixz="7.3565E-07" iyy="0.0002583" iyz="-3.2917E-07" izz="0.0003009" />
    </inertial>
    <visual>
      <origin xyz="0 0 0" rpy="0 0 0" />
      <geometry>
        <mesh filename="meshes/R4_Link.STL" />
      </geometry>
      <material name="">
        <color rgba="0.75294 0.75294 0.75294 1" />
      </material>
    </visual>
    <collision>
      <origin xyz="0 0 0" rpy="0 0 0" />
      <geometry>
        <mesh filename="meshes/R4_Link.STL" />
      </geometry>
    </collision>
  </link>
  <joint name="R4_JOINT" type="revolute">
    <origin xyz="0 -0.027 -0.126" rpy="0 0 0" />
    <parent link="R3_Link" />
    <child link="R4_Link" />
    <axis xyz="0 1 0" />
    <limit lower="-1.74" upper="0.78" effort="36" velocity="10.47" />
  </joint>
  <link name="R5_Link">
    <inertial>
      <origin xyz="-0.00021828 -0.0066872 -0.038708" rpy="0 0 0" />
      <mass value="0.40822" />
      <inertia ixx="0.00012359" ixy="5.1816E-07" ixz="-1.9028E-06" iyy="0.00020705" iyz="4.8389E-07" izz="0.00012048" />
    </inertial>
    <visual>
      <origin xyz="0 0 0" rpy="0 0 0" />
      <geometry>
        <mesh filename="meshes/R5_Link.STL" />
      </geometry>
      <material name="">
        <color rgba="0.75294 0.75294 0.75294 1" />
      </material>
    </visual>
    <collision>
      <origin xyz="0 0 0" rpy="0 0 0" />
      <geometry>
        <mesh filename="meshes/R5_Link.STL" />
      </geometry>
    </collision>
  </link>
  <joint name="R5_JOINT" type="revolute">
    <origin xyz="0 0.027 -0.136" rpy="0 0 0" />
    <parent link="R4_Link" />
    <child link="R5_Link" />
    <axis xyz="0 0 1" />
    <limit lower="-2.96" upper="2.96" effort="14" velocity="27.21" />
  </joint>
  <link name="R6_Link">
    <inertial>
      <origin xyz="0.0040737 0.027681 -0.06647" rpy="0 0 0" />
      <mass value="0.45236" />
      <inertia ixx="0.00027533" ixy="6.3462E-07" ixz="4.1417E-07" iyy="0.00019419" iyz="-2.3033E-06" izz="0.00014197" />
    </inertial>
    <visual>
      <origin xyz="0 0 0" rpy="0 0 0" />
      <geometry>
        <mesh filename="meshes/R6_Link.STL" />
      </geometry>
      <material name="">
        <color rgba="0.75294 0.75294 0.75294 1" />
      </material>
    </visual>
    <collision>
      <origin xyz="0 0 0" rpy="0 0 0" />
      <geometry>
        <mesh filename="meshes/R6_Link.STL" />
      </geometry>
    </collision>
  </link>
  <joint name="R6_JOINT" type="revolute">
    <origin xyz="0 -0.028 -0.0435" rpy="0 0 0" />
    <parent link="R5_Link" />
    <child link="R6_Link" />
    <axis xyz="0 1 0" />
    <limit lower="-1.57" upper="1.57" effort="14" velocity="27.21" />
  </joint>
  <link name="R7_Link">
    <inertial>
      <origin xyz="-0.02543 0.00014767 -0.031537" rpy="0 0 0" />
      <mass value="0.080008" />
      <inertia ixx="2.9694E-05" ixy="-1.011E-15" ixz="2.2449E-07" iyy="2.8296E-05" iyz="6.8933E-20" izz="2.5785E-05" />
    </inertial>
    <visual>
      <origin xyz="0 0 0" rpy="0 0 0" />
      <geometry>
        <mesh filename="meshes/R7_Link.STL" />
      </geometry>
      <material name="">
        <color rgba="0.75294 0.75294 0.75294 1" />
      </material>
    </visual>
    <collision>
      <origin xyz="0 0 0" rpy="0 0 0" />
      <geometry>
        <mesh filename="meshes/R7_Link.STL" />
      </geometry>
    </collision>
  </link>
  <joint name="R7_JOINT" type="revolute">
    <origin xyz="0.028 0.028 -0.075" rpy="0 0 0" />
    <parent link="R6_Link" />
    <child link="R7_Link" />
    <axis xyz="-1 0 0" />
    <limit lower="-1.57" upper="1.57" effort="14" velocity="27.21" />
  </joint>
</robot>
