<?xml version='1.0' encoding='utf-8'?>
<robot name="arm_lingzuV2_left">
  <link name="base_link">
    <inertial>
      <origin xyz="1.6001E-05 9.5162E-07 -1.3045E-05" rpy="0 0 0" />
      <mass value="3.5229" />
      <inertia ixx="0.0038728" ixy="-5.3821E-11" ixz="2.031E-09" iyy="0.0057823" iyz="2.5825E-07" izz="0.0039027" />
    </inertial>
    <visual>
      <origin xyz="0 0 0" rpy="0 0 0" />
      <geometry>
        <mesh filename="meshes/base_link.STL" />
      </geometry>
      <material name="">
        <color rgba="0.75294 0.75294 0.75294 1" />
      </material>
    </visual>
    <collision>
      <origin xyz="0 0 0" rpy="0 0 0" />
      <geometry>
        <mesh filename="meshes/base_link.STL" />
      </geometry>
    </collision>
  </link>
  <link name="L1_Link">
    <inertial>
      <origin xyz="0.0055935 0.067095 1.6101E-05" rpy="0 0 0" />
      <mass value="1.1399" />
      <inertia ixx="0.0015292" ixy="5.3473E-07" ixz="4.6353E-07" iyy="0.00082003" iyz="-1.2213E-05" izz="0.00086293" />
    </inertial>
    <visual>
      <origin xyz="0 0 0" rpy="0 0 0" />
      <geometry>
        <mesh filename="meshes/L1_Link.STL" />
      </geometry>
      <material name="">
        <color rgba="0.75294 0.75294 0.75294 1" />
      </material>
    </visual>
    <collision>
      <origin xyz="0 0 0" rpy="0 0 0" />
      <geometry>
        <mesh filename="meshes/L1_Link.STL" />
      </geometry>
    </collision>
  </link>
  <joint name="L1_JOINT" type="revolute">
    <origin xyz="0 0.1435 0" rpy="0 0 0" />
    <parent link="base_link" />
    <child link="L1_Link" />
    <axis xyz="0 -1 0" />
    <limit lower="-2.18" upper="3.75" effort="60" velocity="18.84" />
  </joint>
  <link name="L2_Link">
    <inertial>
      <origin xyz="-0.030824 -0.00089644 -0.10575" rpy="0 0 0" />
      <mass value="0.87525" />
      <inertia ixx="0.00059856" ixy="-1.6711E-07" ixz="2.763E-07" iyy="0.00056465" iyz="1.2297E-06" izz="0.00082507" />
    </inertial>
    <visual>
      <origin xyz="0 0 0" rpy="0 0 0" />
      <geometry>
        <mesh filename="meshes/L2_Link.STL" />
      </geometry>
      <material name="">
        <color rgba="0.75294 0.75294 0.75294 1" />
      </material>
    </visual>
    <collision>
      <origin xyz="0 0 0" rpy="0 0 0" />
      <geometry>
        <mesh filename="meshes/L2_Link.STL" />
      </geometry>
    </collision>
  </link>
  <joint name="L2_JOINT" type="revolute">
    <origin xyz="0.03125 0.0715 0" rpy="0 0 0" />
    <parent link="L1_Link" />
    <child link="L2_Link" />
    <axis xyz="-1 0 0" />
    <limit lower="-3.33" upper="0.19" effort="60" velocity="18.84" />
  </joint>
  <link name="L3_Link">
    <inertial>
      <origin xyz="-6.3316E-05 0.002738 -0.1019" rpy="0 0 0" />
      <mass value="0.8795" />
      <inertia ixx="0.00048022" ixy="2.8138E-08" ixz="4.5141E-08" iyy="0.0007768" iyz="5.0522E-07" izz="0.00049364" />
    </inertial>
    <visual>
      <origin xyz="0 0 0" rpy="0 0 0" />
      <geometry>
        <mesh filename="meshes/L3_Link.STL" />
      </geometry>
      <material name="">
        <color rgba="0.75294 0.75294 0.75294 1" />
      </material>
    </visual>
    <collision>
      <origin xyz="0 0 0" rpy="0 0 0" />
      <geometry>
        <mesh filename="meshes/L3_Link.STL" />
      </geometry>
    </collision>
  </link>
  <joint name="L3_JOINT" type="revolute">
    <origin xyz="-0.03125 0 -0.147" rpy="0 0 0" />
    <parent link="L2_Link" />
    <child link="L3_Link" />
    <axis xyz="0 0 1" />
    <limit lower="-2.26" upper="2.26" effort="17" velocity="137.68" />
  </joint>
  <link name="L4_Link">
    <inertial>
      <origin xyz="-2.7099E-05 -0.026756 -0.095506" rpy="0 0 0" />
      <mass value="0.53116" />
      <inertia ixx="0.0002451" ixy="4.3022E-09" ixz="7.2993E-07" iyy="0.00025828" iyz="3.2922E-07" izz="0.00030089" />
    </inertial>
    <visual>
      <origin xyz="0 0 0" rpy="0 0 0" />
      <geometry>
        <mesh filename="meshes/L4_Link.STL" />
      </geometry>
      <material name="">
        <color rgba="0.75294 0.75294 0.75294 1" />
      </material>
    </visual>
    <collision>
      <origin xyz="0 0 0" rpy="0 0 0" />
      <geometry>
        <mesh filename="meshes/L4_Link.STL" />
      </geometry>
    </collision>
  </link>
  <joint name="L4_JOINT" type="revolute">
    <origin xyz="0 0.027 -0.126" rpy="0 0 0" />
    <parent link="L3_Link" />
    <child link="L4_Link" />
    <axis xyz="0 -1 0" />
    <limit lower="-0.78" upper="1.74" effort="36" velocity="10.47" />
  </joint>
  <link name="L5_Link">
    <inertial>
      <origin xyz="0.00013865 0.0050189 -0.038216" rpy="0 0 0" />
      <mass value="0.38227" />
      <inertia ixx="0.00011219" ixy="5.1813E-07" ixz="-1.7847E-06" iyy="0.00018792" iyz="5.7521E-07" izz="0.00011281" />
    </inertial>
    <visual>
      <origin xyz="0 0 0" rpy="0 0 0" />
      <geometry>
        <mesh filename="meshes/L5_Link.STL" />
      </geometry>
      <material name="">
        <color rgba="0.75294 0.75294 0.75294 1" />
      </material>
    </visual>
    <collision>
      <origin xyz="0 0 0" rpy="0 0 0" />
      <geometry>
        <mesh filename="meshes/L5_Link.STL" />
      </geometry>
    </collision>
  </link>
  <joint name="L5_JOINT" type="revolute">
    <origin xyz="0 -0.027 -0.136" rpy="0 0 0" />
    <parent link="L4_Link" />
    <child link="L5_Link" />
    <axis xyz="0 0 1" />
    <limit lower="-2.96" upper="2.96" effort="14" velocity="27.21" />
  </joint>
  <link name="L6_Link">
    <inertial>
      <origin xyz="0.004078 -0.027685 -0.066775" rpy="0 0 0" />
      <mass value="0.45077" />
      <inertia ixx="0.00027533" ixy="-6.3462E-07" ixz="-3.1858E-07" iyy="0.00019418" iyz="-1.1219E-06" izz="0.00014196" />
    </inertial>
    <visual>
      <origin xyz="0 0 0" rpy="0 0 0" />
      <geometry>
        <mesh filename="meshes/L6_Link.STL" />
      </geometry>
      <material name="">
        <color rgba="0.75294 0.75294 0.75294 1" />
      </material>
    </visual>
    <collision>
      <origin xyz="0 0 0" rpy="0 0 0" />
      <geometry>
        <mesh filename="meshes/L6_Link.STL" />
      </geometry>
    </collision>
  </link>
  <joint name="L6_JOINT" type="revolute">
    <origin xyz="0 0.028 -0.0435" rpy="0 0 0" />
    <parent link="L5_Link" />
    <child link="L6_Link" />
    <axis xyz="0 -1 0" />
    <limit lower="-1.57" upper="1.57" effort="14" velocity="27.21" />
  </joint>
  <link name="L7_Link">
    <inertial>
      <origin xyz="-0.02543 -0.00014767 -0.031537" rpy="0 0 0" />
      <mass value="0.080008" />
      <inertia ixx="2.9694E-05" ixy="-1.011E-15" ixz="2.2449E-07" iyy="2.8296E-05" iyz="1.1031E-19" izz="2.5785E-05" />
    </inertial>
    <visual>
      <origin xyz="0 0 0" rpy="0 0 0" />
      <geometry>
        <mesh filename="meshes/L7_Link.STL" />
      </geometry>
      <material name="">
        <color rgba="0.75294 0.75294 0.75294 1" />
      </material>
    </visual>
    <collision>
      <origin xyz="0 0 0" rpy="0 0 0" />
      <geometry>
        <mesh filename="meshes/L7_Link.STL" />
      </geometry>
    </collision>
  </link>
  <joint name="L7_JOINT" type="revolute">
    <origin xyz="0.028 -0.028 -0.075" rpy="0 0 0" />
    <parent link="L6_Link" />
    <child link="L7_Link" />
    <axis xyz="-1 0 0" />
    <limit lower="-1.57" upper="1.57" effort="14" velocity="27.21" />
  </joint>
</robot>
